[2023-05-26T21:55:03.947+0400] {taskinstance.py:1103} INFO - Dependencies all met for dep_context=non-requeueable deps ti=<TaskInstance: podcast_summary.speech_to_text manual__2023-05-26T17:54:34.537631+00:00 [queued]>
[2023-05-26T21:55:03.956+0400] {taskinstance.py:1103} INFO - Dependencies all met for dep_context=requeueable deps ti=<TaskInstance: podcast_summary.speech_to_text manual__2023-05-26T17:54:34.537631+00:00 [queued]>
[2023-05-26T21:55:03.956+0400] {taskinstance.py:1308} INFO - Starting attempt 1 of 1
[2023-05-26T21:55:03.973+0400] {taskinstance.py:1327} INFO - Executing <Task(_PythonDecoratedOperator): speech_to_text> on 2023-05-26 17:54:34.537631+00:00
[2023-05-26T21:55:04.000+0400] {standard_task_runner.py:57} INFO - Started process 239 to run task
[2023-05-26T21:55:04.010+0400] {standard_task_runner.py:84} INFO - Running: ['airflow', 'tasks', 'run', 'podcast_summary', 'speech_to_text', 'manual__2023-05-26T17:54:34.537631+00:00', '--job-id', '132', '--raw', '--subdir', 'DAGS_FOLDER/podcast_summary.py', '--cfg-path', '/tmp/tmp19ayq8o2']
[2023-05-26T21:55:04.014+0400] {standard_task_runner.py:85} INFO - Job 132: Subtask speech_to_text
[2023-05-26T21:55:04.075+0400] {task_command.py:410} INFO - Running <TaskInstance: podcast_summary.speech_to_text manual__2023-05-26T17:54:34.537631+00:00 [running]> on host DESKTOP-V010GL9.localdomain
[2023-05-26T21:55:04.155+0400] {taskinstance.py:1545} INFO - Exporting env vars: AIRFLOW_CTX_DAG_OWNER='airflow' AIRFLOW_CTX_DAG_ID='podcast_summary' AIRFLOW_CTX_TASK_ID='speech_to_text' AIRFLOW_CTX_EXECUTION_DATE='2023-05-26T17:54:34.537631+00:00' AIRFLOW_CTX_TRY_NUMBER='1' AIRFLOW_CTX_DAG_RUN_ID='manual__2023-05-26T17:54:34.537631+00:00'
[2023-05-26T21:55:04.162+0400] {base.py:73} INFO - Using connection ID 'podcasts' for task execution.
[2023-05-26T21:55:06.779+0400] {logging_mixin.py:149} INFO - Transcribing what-you-miss-when-you-miss-watercooler-conversations.mp3
[2023-05-26T22:03:37.448+0400] {local_task_job_runner.py:115} ERROR - Received SIGTERM. Terminating subprocesses
[2023-05-26T22:03:37.463+0400] {process_utils.py:131} INFO - Sending Signals.SIGTERM to group 239. PIDs of all processes in the group: [753, 239]
[2023-05-26T22:03:37.464+0400] {process_utils.py:86} INFO - Sending the signal Signals.SIGTERM to group 239
[2023-05-26T22:03:37.479+0400] {taskinstance.py:1517} ERROR - Received SIGTERM. Terminating subprocesses.
[2023-05-26T22:03:37.515+0400] {taskinstance.py:1824} ERROR - Task failed with exception
Traceback (most recent call last):
  File "/home/chinnu/.local/lib/python3.10/site-packages/airflow/decorators/base.py", line 220, in execute
    return_value = super().execute(context)
  File "/home/chinnu/.local/lib/python3.10/site-packages/airflow/operators/python.py", line 181, in execute
    return_value = self.execute_callable()
  File "/home/chinnu/.local/lib/python3.10/site-packages/airflow/operators/python.py", line 198, in execute_callable
    return self.python_callable(*self.op_args, **self.op_kwargs)
  File "/home/chinnu/airflow/dags/podcast_summary.py", line 103, in speech_to_text
    mp3 = AudioSegment.from_mp3(filepath)
  File "/home/chinnu/.local/lib/python3.10/site-packages/pydub/audio_segment.py", line 796, in from_mp3
    return cls.from_file(file, 'mp3', parameters=parameters)
  File "/home/chinnu/.local/lib/python3.10/site-packages/pydub/audio_segment.py", line 768, in from_file
    p_out, p_err = p.communicate(input=stdin_data)
  File "/usr/lib/python3.10/subprocess.py", line 1152, in communicate
    stdout, stderr = self._communicate(input, endtime, timeout)
  File "/usr/lib/python3.10/subprocess.py", line 2003, in _communicate
    ready = selector.select(timeout)
  File "/usr/lib/python3.10/selectors.py", line 416, in select
    fd_event_list = self._selector.poll(timeout)
  File "/home/chinnu/.local/lib/python3.10/site-packages/airflow/models/taskinstance.py", line 1519, in signal_handler
    raise AirflowException("Task received SIGTERM signal")
airflow.exceptions.AirflowException: Task received SIGTERM signal
[2023-05-26T22:03:37.745+0400] {taskinstance.py:1345} INFO - Marking task as FAILED. dag_id=podcast_summary, task_id=speech_to_text, execution_date=20230526T175434, start_date=20230526T180214, end_date=20230526T180337
[2023-05-26T22:03:37.782+0400] {standard_task_runner.py:104} ERROR - Failed to execute job 132 for task speech_to_text ((sqlite3.OperationalError) disk I/O error
(Background on this error at: https://sqlalche.me/e/14/e3q8); 239)
[2023-05-26T22:03:37.797+0400] {process_utils.py:79} INFO - Process psutil.Process(pid=239, status='terminated', exitcode=1, started='21:55:03') (239) terminated with exit code 1
[2023-05-26T22:03:37.799+0400] {process_utils.py:79} INFO - Process psutil.Process(pid=753, status='terminated', started='21:55:07') (753) terminated with exit code None
[2023-05-26T22:03:37.799+0400] {local_task_job_runner.py:225} INFO - Task exited with return code 143
[2023-05-26T22:03:37.824+0400] {taskinstance.py:2651} INFO - 0 downstream tasks scheduled from follow-on schedule check
[2023-05-26T22:03:37.848+0400] {job.py:216} ERROR - Job heartbeat got an exception
Traceback (most recent call last):
  File "/home/chinnu/.local/lib/python3.10/site-packages/sqlalchemy/engine/base.py", line 1094, in _commit_impl
    self.engine.dialect.do_commit(self.connection)
  File "/home/chinnu/.local/lib/python3.10/site-packages/sqlalchemy/engine/default.py", line 686, in do_commit
    dbapi_connection.commit()
sqlite3.OperationalError: disk I/O error

The above exception was the direct cause of the following exception:

Traceback (most recent call last):
  File "/home/chinnu/.local/lib/python3.10/site-packages/airflow/jobs/job.py", line 208, in heartbeat
    session.commit()
  File "/home/chinnu/.local/lib/python3.10/site-packages/sqlalchemy/orm/session.py", line 1454, in commit
    self._transaction.commit(_to_root=self.future)
  File "/home/chinnu/.local/lib/python3.10/site-packages/sqlalchemy/orm/session.py", line 839, in commit
    trans.commit()
  File "/home/chinnu/.local/lib/python3.10/site-packages/sqlalchemy/engine/base.py", line 2464, in commit
    self._do_commit()
  File "/home/chinnu/.local/lib/python3.10/site-packages/sqlalchemy/engine/base.py", line 2654, in _do_commit
    self._connection_commit_impl()
  File "/home/chinnu/.local/lib/python3.10/site-packages/sqlalchemy/engine/base.py", line 2625, in _connection_commit_impl
    self.connection._commit_impl()
  File "/home/chinnu/.local/lib/python3.10/site-packages/sqlalchemy/engine/base.py", line 1096, in _commit_impl
    self._handle_dbapi_exception(e, None, None, None, None)
  File "/home/chinnu/.local/lib/python3.10/site-packages/sqlalchemy/engine/base.py", line 2129, in _handle_dbapi_exception
    util.raise_(
  File "/home/chinnu/.local/lib/python3.10/site-packages/sqlalchemy/util/compat.py", line 211, in raise_
    raise exception
  File "/home/chinnu/.local/lib/python3.10/site-packages/sqlalchemy/engine/base.py", line 1094, in _commit_impl
    self.engine.dialect.do_commit(self.connection)
  File "/home/chinnu/.local/lib/python3.10/site-packages/sqlalchemy/engine/default.py", line 686, in do_commit
    dbapi_connection.commit()
sqlalchemy.exc.OperationalError: (sqlite3.OperationalError) disk I/O error
(Background on this error at: https://sqlalche.me/e/14/e3q8)
[2023-05-26T22:03:37.882+0400] {local_task_job_runner.py:202} ERROR - Heartbeat time limit exceeded!
